Workbook

Sheet Summary
A1: l
A2: l | B2: l | C2: l | D2: l | E2: l
B3: l
A4: মূল সূচক
A5: মোট submission | B5: =COUNTA('Form Responses 1'!$B$2:$B$51) -> 50
A6: সম্মতি দেননি (Q1 = না → submit) | B6: =COUNTIF('Form Responses 1'!$B$2:$B$51,"না") -> 1
A7: সম্মতি দিয়েছেন (base) | B7: =COUNTIF('Form Responses 1'!$B$2:$B$51,"হ্যাঁ, বয়স ১৮ বছর বা বেশি এবং আমি রাজি") -> 49
A8: ৩০–৪৬ বছর বয়সী (Simulation key শিট থেকে) | B8: =COUNTIFS('Simulation key'!$D$2:$D$50,">=30",'Simulation key'!$D$2:$D$50,"<=46")/$B$7 -> 0.20408163
A9: Q17 আকর্ষণীয় (4–5) | B9: =(COUNTIF('Form Responses 1'!$R$2:$R$51,4)+COUNTIF('Form Responses 1'!$R$2:$R$51,5))/$B$7 -> 0.7755102
A10: Q18 আলাদা মনে হয় (4–5) | B10: =(COUNTIF('Form Responses 1'!$S$2:$S$51,4)+COUNTIF('Form Responses 1'!$S$2:$S$51,5))/$B$7 -> 0.7755102
A11: Q19 কিনে দেখতাম (অবশ্যই + সম্ভবত) | B11: =(COUNTIF('Form Responses 1'!$T$2:$T$51,"অবশ্যই কিনে দেখতাম")+COUNTIF('Form Responses 1'!$T$2:$T$51,"সম্ভবত কিনে দেখতাম"))/$B$7 -> 0.7755102
A12: Q21 ৳360-এ কিনে দেখতাম (অবশ্যই + সম্ভবত) | B12: =(COUNTIF('Form Responses 1'!$V$2:$V$51,"অবশ্যই কিনে দেখতাম")+COUNTIF('Form Responses 1'!$V$2:$V$51,"সম্ভবত কিনে দেখতাম"))/$B$7 -> 0.67346939
A13: Q20 সর্বোচ্চ দাম — উত্তর দিয়েছেন (n) | B13: =COUNT('Form Responses 1'!$U$2:$U$51) -> 47
A14: Q20 সর্বোচ্চ দাম — median (৳) | B14: =MEDIAN('Form Responses 1'!$U$2:$U$51) -> 320
A15: Q20 সর্বোচ্চ দাম — গড় (৳) | B15: =AVERAGE('Form Responses 1'!$U$2:$U$51) -> 321.91489
A16: Q20 ≥ ৳360 বলেছেন (উত্তরদাতাদের %) | B16: =COUNTIF('Form Responses 1'!$U$2:$U$51,">=360")/COUNT('Form Responses 1'!$U$2:$U$51) -> 0.31914894
A17: Q8 সর্বশেষ প্যাকেটের দাম — median (৳) | B17: =MEDIAN('Form Responses 1'!$I$2:$I$51) -> 350
A18: Q11 লিখেছেন (n) | B18: =COUNTA('Q11 কোডিং'!$B$2:$B$42) -> 41
A19: Q11-এ নিজে থেকে পানি উল্লেখ (সব উত্তরদাতার %) | B19: =COUNTIF('Q11 কোডিং'!$C$2:$C$42,"হ্যাঁ")/$B$7 -> 0.42857143
A21: Q2. বয়সের সীমা | B21: সংখ্যা | C21: %
A22: ১৮–২৪ | B22: =COUNTIF('Form Responses 1'!$C$2:$C$51,A22) -> 30 | C22: =B22/$B$7 -> 0.6122449
A23: ২৫–৩৪ | B23: =COUNTIF('Form Responses 1'!$C$2:$C$51,A23) -> 11 | C23: =B23/$B$7 -> 0.2244898
A24: ৩৫–৪৪ | B24: =COUNTIF('Form Responses 1'!$C$2:$C$51,A24) -> 5 | C24: =B24/$B$7 -> 0.10204082
A25: ৪৫–৫৪ | B25: =COUNTIF('Form Responses 1'!$C$2:$C$51,A25) -> 2 | C25: =B25/$B$7 -> 0.040816327
A26: ৫৫ বা বেশি | B26: =COUNTIF('Form Responses 1'!$C$2:$C$51,A26) -> 1 | C26: =B26/$B$7 -> 0.020408163
A28: Q3. লিঙ্গ পরিচয় (optional — ফাঁকাও আছে) | B28: সংখ্যা | C28: %
A29: নারী | B29: =COUNTIF('Form Responses 1'!$D$2:$D$51,A29) -> 25 | C29: =B29/$B$7 -> 0.51020408
A30: পুরুষ | B30: =COUNTIF('Form Responses 1'!$D$2:$D$51,A30) -> 21 | C30: =B30/$B$7 -> 0.42857143
A31: অন্য পরিচয় | B31: =COUNTIF('Form Responses 1'!$D$2:$D$51,A31) -> 0 | C31: =B31/$B$7 -> 0
A32: বলতে চাই না | B32: =COUNTIF('Form Responses 1'!$D$2:$D$51,A32) -> 1 | C32: =B32/$B$7 -> 0.020408163
A34: Q4. থাকার ব্যবস্থা | B34: সংখ্যা | C34: %
A35: শিক্ষার্থী হিসেবে হোস্টেল বা মেসে থাকি | B35: =COUNTIF('Form Responses 1'!$E$2:$E$51,A35) -> 22 | C35: =B35/$B$7 -> 0.44897959
A36: শিক্ষার্থী নই; মেস বা ভাগাভাগি বাসায় থাকি | B36: =COUNTIF('Form Responses 1'!$E$2:$E$51,A36) -> 5 | C36: =B36/$B$7 -> 0.10204082
A37: পরিবারের সঙ্গে বাসায় থাকি | B37: =COUNTIF('Form Responses 1'!$E$2:$E$51,A37) -> 16 | C37: =B37/$B$7 -> 0.32653061
A38: একা বা নিজের সংসার নিয়ে আলাদা বাসায় থাকি | B38: =COUNTIF('Form Responses 1'!$E$2:$E$51,A38) -> 5 | C38: =B38/$B$7 -> 0.10204082
A39: অন্য (নিজে লেখা) | B39: =COUNTA('Form Responses 1'!$E$2:$E$51)-SUM(B35:B38) -> 1 | C39: =B39/$B$7 -> 0.020408163
A40: অন্য-তে লেখা: “কোম্পানির দেওয়া ডরমিটরিতে থাকি”
A42: Q9. সপ্তাহে কতবার শ্যাম্পু | B42: সংখ্যা | C42: %
A43: শ্যাম্পু ব্যবহার করি না | B43: =COUNTIF('Form Responses 1'!$J$2:$J$51,A43) -> 1 | C43: =B43/$B$7 -> 0.020408163
A44: সপ্তাহে একবারের কম | B44: =COUNTIF('Form Responses 1'!$J$2:$J$51,A44) -> 1 | C44: =B44/$B$7 -> 0.020408163
...

Sheet Form Responses 1
A1: Timestamp | B1: Q1. আপনার বয়স কি ১৮ বছর বা বেশি এবং আপনি স্বেচ্ছায় অংশগ্রহণ ও পরিচয় প্রকাশ না করে গবেষণা/প্রেজেন্টেশনে উত্তর ব্যবহারে সম্মতি দিচ্ছেন? | C1: Q2. আপনার বয়সের সীমা কোনটি? | D1: Q3. আপনার লিঙ্গ পরিচয় কী? | E1: Q4. বর্তমানে আপনার থাকার ব্যবস্থা কোনটি? | F1: Q5. বর্তমানে কোন জেলা ও উপজেলা/শহরে থাকেন? | G1: Q6. বর্তমানে সবচেয়ে বেশি কোন ব্র্যান্ড ও ভ্যারিয়েন্টের শ্যাম্পু ব্যবহার করেন? | H1: Q7. সর্বশেষ কেনা শ্যাম্পুর প্যাকেটে কত মিলিলিটার ছিল? | I1: Q8. ওই একই প্যাকেটটির জন্য বাস্তবে কত টাকা দিয়েছিলেন? | J1: Q9. সাধারণত সপ্তাহে কতবার শ্যাম্পু দিয়ে চুল ধোন? | K1: Q10. গত তিন মাসে চুল বা চুল ধোয়া নিয়ে নিচের কোন অভিজ্ঞতাগুলো হয়েছে? | L1: Q11. এসব সমস্যার কারণ কী হতে পারে বলে আপনার মনে হয়? | M1: Q12. চুল ধোয়ার জন্য প্রধানত কোন উৎসের পানি ব্যবহার করেন? | N1: Q13. গত ১২ মাসে বাসা বদল বা অন্য কারণে চুল ধোয়ার পানির উৎস কি বদলেছে? | O1: Q14. পানি বদলে থাকলে, এরপর চুল বা চুল ধোয়ার অভিজ্ঞতা কেমন হয়েছে? | P1: Q15. আপনার ব্যবহৃত পানি বা বাথরুমে নিচের কোনটি আগে থেকে খেয়াল করেছেন? | Q1: Q16. চুল বা চুল ধোয়ার সমস্যা সামলাতে ইতিমধ্যে কী কী করেছেন? | R1: Q17. ধারণাটি আপনার কাছে কতটা আকর্ষণীয়? | S1: Q18. বর্তমানে আপনার জানা শ্যাম্পুগুলোর তুলনায় ধারণাটি কতটা আলাদা মনে হচ্ছে? | T1: Q19. এই ধারণার ভিত্তিতে পণ্যটি কিনে দেখার বিষয়ে আপনার আগ্রহ কোনটির কাছাকাছি? | U1: Q20. বর্ণিত সুবিধাসহ 340 ml বোতলের জন্য সর্বোচ্চ কত টাকা দিতে স্বচ্ছন্দ হতেন? | V1: Q21. বর্ণিত সুবিধাসহ 340 ml বোতলের দাম 360 টাকা হলে আপনি কিনে দেখতে কতটা আগ্রহী হতেন? | W1: Q22. প্রথমবার চেষ্টা করার জন্য কোন প্যাকেটটি বেছে নিতেন? | X1: Q23. ধারণাটির কোন একটি দিক আপনার কাছে সবচেয়ে মূল্যবান? | Y1: Q24. একই ফর্মুলার 340 ml বোতলের এই কাল্পনিক দুটি বিকল্পের মধ্যে কোনটি বেছে নিতেন? | Z1: Q25. কেনার আগে আপনার সবচেয়ে বড় প্রশ্ন বা সংশয় কোনটি হবে? | AA1: Q26. ধারণাটির ভালো লাগা, সন্দেহ বা একটি পরিবর্তনের পরামর্শ নিজের ভাষায় লিখুন।
A2: 46298.818 | B2: হ্যাঁ, বয়স ১৮ বছর বা বেশি এবং আমি রাজি | C2: ১৮–২৪ | D2: নারী | E2: শিক্ষার্থী হিসেবে হোস্টেল বা মেসে থাকি | F2: ঢাকা, শাহবাগ | G2: Sunsilk Black Shine | H2: 180 | I2: 260 | J2: ২–৩ বার | K2: চুল রুক্ষ বা শুষ্ক লাগা, চুলে জট পড়া, স্বাভাবিকের চেয়ে বেশি চুল পড়ছে বলে মনে হওয়া | L2: হলের পানিতে মনে হয় সমস্যা আছে, বাসায় থাকতে এত চুল পড়ত না। | M2: ওয়াসা বা পৌরসভার সরবরাহ করা পানি | N2: হ্যাঁ | O2: আগের চেয়ে সমস্যা বেশি মনে হয়েছে | P2: বালতি, বেসিন বা বাথরুমে হলুদ/কমলা/বাদামি দাগ | Q2: শ্যাম্পুর ব্র্যান্ড বা ভ্যারিয়েন্ট বদলেছি, তেল বা ঘরোয়া যত্ন ব্যবহার করেছি | R2: 5 | S2: 4 | T2: অবশ্যই কিনে দেখতাম | U2: 350 | V2: সম্ভবত কিনে দেখতাম | W2: 340 ml বোতল, ঢাকনায় hardness strip-সহ — 360 টাকা | X2: চুলে পানির খনিজ জমা পরিষ্কার করার উদ্দেশ্যে তৈরি ফর্মুলা | Y2: B: ঢাকনায় hardness test strip আছে — 360 টাকা | Z2: ফর্মুলাটি বাস্তবে কাজ করবে কি না | AA2: হলের মেয়েদের জন্য খুব দরকারি জিনিস। স্যাশেতেও যদি এই ফর্মুলা পাওয়া যায় তাহলে আগে ট্রাই করে দেখা যাবে।
A3: 46298.835 | B3: হ্যাঁ, বয়স ১৮ বছর বা বেশি এবং আমি রাজি | C3: ১৮–২৪ | D3: পুরুষ | E3: শিক্ষার্থী হিসেবে হোস্টেল বা মেসে থাকি | F3: Rajshahi, Motihar | G3: Clear men cool sport menthol | H3: 180 | I3: 330 | J3: ৪–৫ বার | K3: চুল রুক্ষ বা শুষ্ক লাগা, চুল ধোয়ার পরও জমাট বা অবশিষ্ট কিছু থাকার অনুভূতি, খুশকি বা মাথার ত্বকে চুলকানি | L3: রাজশাহীর পানি খর, বালতিতে সাদা দাগ পড়ে যায়। চুলেও মনে হয় ওইটাই জমে। | M3: গভীর নলকূপ | N3: হ্যাঁ | O3: আগের চেয়ে সমস্যা বেশি মনে হয়েছে | P3: কল বা পাত্রে সাদা জমাট দাগ | Q3: শ্যাম্পুর ব্র্যান্ড বা ভ্যারিয়েন্ট বদলেছি | R3: 5 | S3: 5 | T3: অবশ্যই কিনে দেখতাম | U3: 400 | V3: অবশ্যই কিনে দেখতাম | W3: 340 ml বোতল, ঢাকনায় hardness strip-সহ — 360 টাকা | X3: ঢাকনায় hardness test strip | Y3: B: ঢাকনায় hardness test strip আছে — 360 টাকা | Z3: Strip-এর ফল কতটা নির্ভরযোগ্য | AA3: strip টা ভালো আইডিয়া, তবে একবার ব্যবহার করলে শেষ নাকি বারবার করা যাবে সেটা পরিষ্কার না। একাধিক strip দিলে ভালো হয়।
A4: 46298.838 | B4: হ্যাঁ, বয়স ১৮ বছর বা বেশি এবং আমি রাজি | C4: ২৫–৩৪ | D4: নারী | E4: পরিবারের সঙ্গে বাসায় থাকি | F4: চট্টগ্রাম, পাঁচলাইশ | G4: Dove hair fall rescue | H4: 340 | I4: 520 | J4: ২–৩ বার | K4: চুল ভেঙে যাওয়া, স্বাভাবিকের চেয়ে বেশি চুল পড়ছে বলে মনে হওয়া | L4: ডেলিভারির পর থেকে চুল পড়া বেড়েছে, হরমোনের কারণে হতে পারে। | M4: ওয়াসা বা পৌরসভার সরবরাহ করা পানি | N4: না | O4: প্রযোজ্য নয়—পানি বদলায়নি | P4: খেয়াল করিনি বা জানি না | Q4: শ্যাম্পুর ব্র্যান্ড বা ভ্যারিয়েন্ট বদলেছি, তেল বা ঘরোয়া যত্ন ব্যবহার করেছি, চিকিৎসক বা অন্য বিশেষজ্ঞের পরামর্শ নিয়েছি | R4: 3 | S4: 4 | T4: এখনো সিদ্ধান্ত নিতে পারছি না | U4: 300 | V4: এখনো সিদ্ধান্ত নিতে পারছি না | W4: 6 ml স্যাশে — 3 টাকা | X4: কম টাকা খরচ করে স্যাশে দিয়ে চেষ্টা করার সুযোগ | Y4: দুটির মধ্যে বিশেষ পছন্দ নেই | Z4: আমার চুল বা মাথার ত্বকের সঙ্গে মানাবে কি না | AA4: আমার সমস্যা পানির কারণে কিনা নিশ্চিত না। আগে বুঝতে চাই কাদের জন্য এটা।
A5: 46298.858 | B5: হ্যাঁ, বয়স ১৮ বছর বা বেশি এবং আমি রাজি | C5: ১৮–২৪ | D5: পুরুষ | E5: শিক্ষার্থী হিসেবে হোস্টেল বা মেসে থাকি | F5: Khulna, Batiaghata | G5: Head & Shoulders cool menthol | H5: 180 | I5: 350 | J5: ২–৩ বার | K5: চুল রুক্ষ বা শুষ্ক লাগা, শ্যাম্পুতে কম ফেনা হওয়া, খুশকি বা মাথার ত্বকে চুলকানি | L5: পানি লবণাক্ত, ফেনা হয়না ঠিকমতো | M5: গভীর নলকূপ | N5: হ্যাঁ | O5: আগের চেয়ে সমস্যা বেশি মনে হয়েছে | P5: ব্যবহৃত পানি নোনতা বলে আগে থেকেই মনে হয়েছে | Q5: শ্যাম্পুর ব্র্যান্ড বা ভ্যারিয়েন্ট বদলেছি, ফিল্টার করা বা কিনে আনা পানি ব্যবহার করেছি | R5: 4 | S5: 5 | T5: সম্ভবত কিনে দেখতাম | U5: 300 | V5: সম্ভবত কিনে দেখতাম | W5: 180 ml বোতল — 180 টাকা | X5: চুলে পানির খনিজ জমা পরিষ্কার করার উদ্দেশ্যে তৈরি ফর্মুলা | Y5: B: ঢাকনায় hardness test strip আছে — 360 টাকা | Z5: ফর্মুলাটি বাস্তবে কাজ করবে কি না | AA5: লবণ পানির এলাকার জন্যও কিছু করা যায় কি না দেখবেন। strip শুধু hardness দেখায় এটা বলায় ভালো লাগলো, সৎ মনে হয়েছে।
A6: 46298.86 | B6: হ্যাঁ, বয়স ১৮ বছর বা বেশি এবং আমি রাজি | C6: ১৮–২৪ | D6: নারী | E6: পরিবারের সঙ্গে বাসায় থাকি | F6: Dhaka, Mirpur 10 | G6: Sunsilk thick and long | H6: 340 | I6: 450 | J6: ৪–৫ বার | K6: চুলে জট পড়া, স্বাভাবিকের চেয়ে বেশি চুল পড়ছে বলে মনে হওয়া | L6: জানি না। হয়তো ধুলাবালি। | M6: ওয়াসা বা পৌরসভার সরবরাহ করা পানি | N6: না | O6: প্রযোজ্য নয়—পানি বদলায়নি | P6: বালতি, বেসিন বা বাথরুমে হলুদ/কমলা/বাদামি দাগ | Q6: তেল বা ঘরোয়া যত্ন ব্যবহার করেছি | R6: 4 | S6: 3 | T6: সম্ভবত কিনে দেখতাম | U6: 320 | V6: সম্ভবত কিনে দেখতাম | W6: 6 ml স্যাশে — 3 টাকা | X6: চুলে পানির খনিজ জমা পরিষ্কার করার উদ্দেশ্যে তৈরি ফর্মুলা | Y6: A: সাধারণ ঢাকনা, test strip নেই — 330 টাকা | Z6: দাম উপযুক্ত কি না
A7: 46298.883 | B7: হ্যাঁ, বয়স ১৮ বছর বা বেশি এবং আমি রাজি | C7: ২৫–৩৪ | D7: পুরুষ | E7: শিক্ষার্থী নই; মেস বা ভাগাভাগি বাসায় থাকি | F7: গাজীপুর, টঙ্গী | G7: clear | J7: ৬ বার বা বেশি | K7: চুল ধোয়ার পরও জমাট বা অবশিষ্ট কিছু থাকার অনুভূতি, স্বাভাবিকের চেয়ে বেশি চুল পড়ছে বলে মনে হওয়া, খুশকি বা মাথার ত্বকে চুলকানি | L7: এখানকার পানিতে আয়রন বেশি, সাদা গেঞ্জি হলুদ হয়ে যায়। | M7: জানি না | N7: হ্যাঁ | O7: আগের চেয়ে সমস্যা বেশি মনে হয়েছে | P7: বালতি, বেসিন বা বাথরুমে হলুদ/কমলা/বাদামি দাগ, পানিতে লোহার মত গন্ধ | Q7: শ্যাম্পুর ব্র্যান্ড বা ভ্যারিয়েন্ট বদলেছি | R7: 4 | S7: 4 | T7: সম্ভবত কিনে দেখতাম | U7: 250 | V7: এখনো সিদ্ধান্ত নিতে পারছি না | W7: 6 ml স্যাশে — 3 টাকা | X7: কম টাকা খরচ করে স্যাশে দিয়ে চেষ্টা করার সুযোগ | Y7: A: সাধারণ ঢাকনা, test strip নেই — 330 টাকা | Z7: দাম উপযুক্ত কি না | AA7: দাম একটু বেশি মনে হচ্ছে আমাদের মত মেসে থাকা মানুষের জন্য। স্যাশে থাকলে কিনব।
A8: 46298.901 | B8: হ্যাঁ, বয়স ১৮ বছর বা বেশি এবং আমি রাজি | C8: ১৮–২৪ | D8: নারী | E8: শিক্ষার্থী হিসেবে হোস্টেল বা মেসে থাকি | F8: Sylhet, Akhalia | G8: Pantene hair fall control | H8: 180 | I8: 300 | J8: ২–৩ বার | K8: চুল রুক্ষ বা শুষ্ক লাগা, চুলে জট পড়া, চুল ভেঙে যাওয়া, স্বাভাবিকের চেয়ে বেশি চুল পড়ছে বলে মনে হওয়া | L8: বৃষ্টির সময় চুল বেশি জট পাকে, আর হোস্টেলের পানিও ঠিক না | M8: গভীর নলকূপ | N8: হ্যাঁ | O8: আগের চেয়ে সমস্যা বেশি মনে হয়েছে | P8: বালতি, বেসিন বা বাথরুমে হলুদ/কমলা/বাদামি দাগ, কল বা পাত্রে সাদা জমাট দাগ | Q8: শ্যাম্পুর ব্র্যান্ড বা ভ্যারিয়েন্ট বদলেছি, তেল বা ঘরোয়া যত্ন ব্যবহার করেছি | R8: 5 | S8: 5 | T8: অবশ্যই কিনে দেখতাম | U8: 380 | V8: অবশ্যই কিনে দেখতাম | W8: 340 ml বোতল, ঢাকনায় hardness strip-সহ — 360 টাকা | X8: ঢাকনায় hardness test strip | Y8: B: ঢাকনায় hardness test strip আছে — 360 টাকা | Z8: Strip ব্যবহার করা সহজ হবে কি না | AA8: আমি জানতেই চাই আমাদের হোস্টেলের পানি কেমন। strip দিয়ে বান্ধবীদের সাথে টেস্ট করে দেখতাম 😄
A9: 46298.937 | B9: হ্যাঁ, বয়স ১৮ বছর বা বেশি এবং আমি রাজি | C9: ৩৫–৪৪ | D9: পুরুষ | E9: একা বা নিজের সংসার নিয়ে আলাদা বাসায় থাকি | F9: নারায়ণগঞ্জ সদর | G9: Head and Shoulders | H9: 340 | I9: 580 | J9: ২–৩ বার | K9: খুশকি বা মাথার ত্বকে চুলকানি | L9: খুশকি পুরান সমস্যা। | M9: ওয়াসা বা পৌরসভার সরবরাহ করা পানি | N9: না | O9: প্রযোজ্য নয়—পানি বদলায়নি | P9: বালতি, বেসিন বা বাথরুমে হলুদ/কমলা/বাদামি দাগ | Q9: শ্যাম্পুর ব্র্যান্ড বা ভ্যারিয়েন্ট বদলেছি, চিকিৎসক বা অন্য বিশেষজ্ঞের পরামর্শ নিয়েছি | R9: 3 | S9: 3 | T9: এখনো সিদ্ধান্ত নিতে পারছি না | U9: 400 | V9: এখনো সিদ্ধান্ত নিতে পারছি না | W9: 180 ml বোতল — 180 টাকা | X9: চুলে পানির খনিজ জমা পরিষ্কার করার উদ্দেশ্যে তৈরি ফর্মুলা | Y9: A: সাধারণ ঢাকনা, test strip নেই — 330 টাকা | Z9: বর্তমান শ্যাম্পু বদলানোর যথেষ্ট কারণ আছে কি না | AA9: খুশকির জন্য কাজ করবে কি না সেটা উল্লেখ নাই। H&S ছেড়ে বদলানোর কারণ দেখছি না এখনো।
A10: 46298.978 | B10: না
A11: 46299.628 | B11: হ্যাঁ, বয়স ১৮ বছর বা বেশি এবং আমি রাজি | C11: ১৮–২৪ | D11: নারী | E11: শিক্ষার্থী হিসেবে হোস্টেল বা মেসে থাকি | F11: ঢাকা, মোহাম্মদপুর | G11: Sunsilk stunning black shine (মিনিপ্যাক) | H11: 6 | I11: 5 | J11: ২–৩ বার | K11: চুল রুক্ষ বা শুষ্ক লাগা, শ্যাম্পুতে কম ফেনা হওয়া, চুল ধোয়ার পরও জমাট বা অবশিষ্ট কিছু থাকার অনুভূতি | L11: মেসের পানিতে কেমন যেন গন্ধ, চুল ধোয়ার পর চটচটে লাগে। | M11: ওয়াসা বা পৌরসভার সরবরাহ করা পানি | N11: হ্যাঁ | O11: আগের চেয়ে সমস্যা বেশি মনে হয়েছে | P11: বালতি, বেসিন বা বাথরুমে হলুদ/কমলা/বাদামি দাগ, কল বা পাত্রে সাদা জমাট দাগ | Q11: শ্যাম্পুর ব্র্যান্ড বা ভ্যারিয়েন্ট বদলেছি, ফিল্টার করা বা কিনে আনা পানি ব্যবহার করেছি | R11: 5 | S11: 4 | T11: সম্ভবত কিনে দেখতাম | U11: 300 | V11: সম্ভবত কিনে দেখতাম | W11: 6 ml স্যাশে — 3 টাকা | X11: কম টাকা খরচ করে স্যাশে দিয়ে চেষ্টা করার সুযোগ | Y11: B: ঢাকনায় hardness test strip আছে — 360 টাকা | Z11: দাম উপযুক্ত কি না | AA11: স্যাশে ৩ টাকা হলে অবশ্যই ট্রাই করবো।
A12: 46299.65 | B12: হ্যাঁ, বয়স ১৮ বছর বা বেশি এবং আমি রাজি | C12: ১৮–২৪ | D12: পুরুষ | E12: পরিবারের সঙ্গে বাসায় থাকি | F12: Cumilla Sadar | G12: Clear complete active care | H12: 180 | I12: 320 | J12: ৬ বার বা বেশি | K12: কোনোটিই নয় | M12: গভীর নলকূপ | N12: না | O12: প্রযোজ্য নয়—পানি বদলায়নি | P12: বালতি, বেসিন বা বাথরুমে হলুদ/কমলা/বাদামি দাগ | Q12: কোনো ব্যবস্থা নিইনি | R12: 3 | S12: 4 | T12: সম্ভবত কিনতাম না | U12: 200 | V12: সম্ভবত কিনতাম না | W12: কোনোটিই কিনতাম না | X12: কোনোটিই বিশেষ মূল্যবান মনে হচ্ছে না | Y12: কোনোটিই কিনতাম না | Z12: বর্তমান শ্যাম্পু বদলানোর যথেষ্ট কারণ আছে কি না | AA12: আমার চুলে তেমন সমস্যা নাই তাই দরকার মনে হয় না।
A13: 46299.677 | B13: হ্যাঁ, বয়স ১৮ বছর বা বেশি এবং আমি রাজি | C13: ২৫–৩৪ | D13: নারী | E13: শিক্ষার্থী নই; মেস বা ভাগাভাগি বাসায় থাকি | F13: Dhaka, Badda | G13: TRESemme keratin smooth | H13: 340 | I13: 580 | J13: ২–৩ বার | K13: চুল রুক্ষ বা শুষ্ক লাগা, চুল ভেঙে যাওয়া, স্বাভাবিকের চেয়ে বেশি চুল পড়ছে বলে মনে হওয়া | L13: বাড্ডায় আসার পর থেকে চুল ঝরছে বেশি, পানির কারণে কিনা বুঝি না, আবার কাজের চাপও আছে। | M13: ওয়াসা বা পৌরসভার সরবরাহ করা পানি | N13: হ্যাঁ | O13: আগের চেয়ে সমস্যা বেশি মনে হয়েছে | P13: বালতি, বেসিন বা বাথরুমে হলুদ/কমলা/বাদামি দাগ | Q13: শ্যাম্পুর ব্র্যান্ড বা ভ্যারিয়েন্ট বদলেছি, তেল বা ঘরোয়া যত্ন ব্যবহার করেছি, ফিল্টার করা বা কিনে আনা পানি ব্যবহার করেছি | R13: 5 | S13: 5 | T13: অবশ্যই কিনে দেখতাম | U13: 500 | V13: অবশ্যই কিনে দেখতাম | W13: 340 ml বোতল, ঢাকনায় hardness strip-সহ — 360 টাকা | X13: চুলে পানির খনিজ জমা পরিষ্কার করার উদ্দেশ্যে তৈরি ফর্মুলা | Y13: B: ঢাকনায় hardness test strip আছে — 360 টাকা | Z13: ফর্মুলাটি বাস্তবে কাজ করবে কি না | AA13: কোনো ল্যাব টেস্ট বা dermatologist tested লেখা থাকলে আরো ভরসা পেতাম। বাকিটা দারুণ।
A14: 46299.896 | B14: হ্যাঁ, বয়স ১৮ বছর বা বেশি এবং আমি রাজি | C14: ১৮–২৪ | D14: পুরুষ | E14: শিক্ষার্থী হিসেবে হোস্টেল বা মেসে থাকি | F14: রংপুর সদর | G14: সানসিল্ক, কোনটা মনে নাই | J14: ১ বার | K14: চুল রুক্ষ বা শুষ্ক লাগা, খুশকি বা মাথার ত্বকে চুলকানি | L14: শীত আসলে খুশকি বাড়ে | M14: গভীর নলকূপ | N14: হ্যাঁ | O14: বুঝতে পারিনি | P14: খেয়াল করিনি বা জানি না | Q14: তেল বা ঘরোয়া যত্ন ব্যবহার করেছি | R14: 4 | S14: 4 | T14: সম্ভবত কিনে দেখতাম | U14: 250 | V14: এখনো সিদ্ধান্ত নিতে পারছি না | W14: 6 ml স্যাশে — 3 টাকা | X14: কম টাকা খরচ করে স্যাশে দিয়ে চেষ্টা করার সুযোগ | Y14: A: সাধারণ ঢাকনা, test strip নেই — 330 টাকা | Z14: দাম উপযুক্ত কি না
A15: 46299.897 | B15: হ্যাঁ, বয়স ১৮ বছর বা বেশি এবং আমি রাজি | C15: ১৮–২৪ | D15: নারী | E15: শিক্ষার্থী হিসেবে হোস্টেল বা মেসে থাকি | F15: Noakhali, Sonapur | G15: Dove intense repair | H15: 180 | I15: 280 | J15: ২–৩ বার | K15: চুল রুক্ষ বা শুষ্ক লাগা, চুলে জট পড়া, চুল ধোয়ার পরও জমাট বা অবশিষ্ট কিছু থাকার অনুভূতি, স্বাভাবিকের চেয়ে বেশি চুল পড়ছে বলে মনে হওয়া | L15: নোয়াখালীর পানিতে প্রচুর আয়রন, বালতি লাল হয়ে যায়। চুল খড়ের মত লাগে। | M15: গভীর নলকূপ | N15: হ্যাঁ | O15: আগের চেয়ে সমস্যা বেশি মনে হয়েছে | P15: বালতি, বেসিন বা বাথরুমে হলুদ/কমলা/বাদামি দাগ, কল বা পাত্রে সাদা জমাট দাগ | Q15: শ্যাম্পুর ব্র্যান্ড বা ভ্যারিয়েন্ট বদলেছি, তেল বা ঘরোয়া যত্ন ব্যবহার করেছি, ফিল্টার করা বা কিনে আনা পানি ব্যবহার করেছি | R15: 5 | S15: 5 | T15: অবশ্যই কিনে দেখতাম | U15: 400 | V15: অবশ্যই কিনে দেখতাম | W15: 340 ml বোতল, ঢাকনায় hardness strip-সহ — 360 টাকা | X15: চুলে পানির খনিজ জমা পরিষ্কার করার উদ্দেশ্যে তৈরি ফর্মুলা | Y15: B: ঢাকনায় hardness test strip আছে — 360 টাকা | Z15: ফর্মুলাটি বাস্তবে কাজ করবে কি না | AA15: আয়রন পানির জন্যও যদি কিছু করা যায় তাহলে নোয়াখালী, লক্ষ্মীপুরে খুব চলবে। strip আয়রন মাপে না এটা একটু হতাশ লাগলো।
A16: 46299.933 | B16: হ্যাঁ, বয়স ১৮ বছর বা বেশি এবং আমি রাজি | C16: ২৫–৩৪ | D16: পুরুষ | E16: পরিবারের সঙ্গে বাসায় থাকি | F16: Bogura sadar | G16: Head & Shoulders smooth & silky | H16: 340 | I16: 560 | J16: ৪–৫ বার | K16: স্বাভাবিকের চেয়ে বেশি চুল পড়ছে বলে মনে হওয়া, খুশকি বা মাথার ত্বকে চুলকানি | L16: জানি না | M16: ওয়াসা বা পৌরসভার সরবরাহ করা পানি | N16: না | O16: প্রযোজ্য নয়—পানি বদলায়নি | P16: বালতি, বেসিন বা বাথরুমে হলুদ/কমলা/বাদামি দাগ | Q16: শ্যাম্পুর ব্র্যান্ড বা ভ্যারিয়েন্ট বদলেছি | R16: 4 | S16: 3 | T16: সম্ভবত কিনে দেখতাম | U16: 350 | V16: সম্ভবত কিনে দেখতাম | W16: 180 ml বোতল — 180 টাকা | X16: চুলে পানির খনিজ জমা পরিষ্কার করার উদ্দেশ্যে তৈরি ফর্মুলা | Y16: A: সাধারণ ঢাকনা, test strip নেই — 330 টাকা | Z16: আমার চুল বা মাথার ত্বকের সঙ্গে মানাবে কি না | AA16: anti-dandruff ভার্সন থাকলে ভালো হয়।
A17: 46299.934 | B17: হ্যাঁ, বয়স ১৮ বছর বা বেশি এবং আমি রাজি | C17: ১৮–২৪ | D17: নারী | E17: পরিবারের সঙ্গে বাসায় থাকি | F17: ঢাকা, উত্তরা | G17: L'Oreal Paris extraordinary oil | H17: 175 | I17: 550 | J17: ২–৩ বার | K17: চুল রুক্ষ বা শুষ্ক লাগা, চুলে জট পড়া | L17: চুলে কালার করেছি তাই রুক্ষ হয়ে গেছে মনে হয় | M17: ওয়াসা বা পৌরসভার সরবরাহ করা পানি | N17: না | O17: প্রযোজ্য নয়—পানি বদলায়নি | P17: কোনোটিই নয় | Q17: শ্যাম্পুর ব্র্যান্ড বা ভ্যারিয়েন্ট বদলেছি, তেল বা ঘরোয়া যত্ন ব্যবহার করেছি | R17: 4 | S17: 4 | T17: সম্ভবত কিনে দেখতাম | V17: সম্ভবত কিনে দেখতাম | W17: 6 ml স্যাশে — 3 টাকা | X17: ঢাকনায় hardness test strip | Y17: B: ঢাকনায় hardness test strip আছে — 360 টাকা | Z17: আমার চুল বা মাথার ত্বকের সঙ্গে মানাবে কি না | AA17: কালার করা চুলে ব্যবহার করা যাবে কিনা জানতে চাই। কন্ডিশনারও লাগবে সাথে।
A18: 46299.94 | B18: হ্যাঁ, বয়স ১৮ বছর বা বেশি এবং আমি রাজি | C18: ১৮–২৪ | D18: পুরুষ | E18: শিক্ষার্থী হিসেবে হোস্টেল বা মেসে থাকি | F18: Mymensingh, Trishal | G18: clear anti dandruff | H18: 80 | I18: 140 | J18: ৪–৫ বার | K18: শ্যাম্পুতে কম ফেনা হওয়া, চুল ধোয়ার পরও জমাট বা অবশিষ্ট কিছু থাকার অনুভূতি, খুশকি বা মাথার ত্বকে চুলকানি | L18: ত্রিশালের পানিতে আয়রন আছে, শ্যাম্পু করলে ফেনাই হয় না। | M18: অগভীর নলকূপ | N18: হ্যাঁ | O18: আগের চেয়ে সমস্যা বেশি মনে হয়েছে | P18: বালতি, বেসিন বা বাথরুমে হলুদ/কমলা/বাদামি দাগ | Q18: শ্যাম্পুর ব্র্যান্ড বা ভ্যারিয়েন্ট বদলেছি | R18: 4 | S18: 5 | T18: সম্ভবত কিনে দেখতাম | U18: 280 | V18: সম্ভবত কিনতাম না | W18: 6 ml স্যাশে — 3 টাকা | X18: কম টাকা খরচ করে স্যাশে দিয়ে চেষ্টা করার সুযোগ | Y18: A: সাধারণ ঢাকনা, test strip নেই — 330 টাকা | Z18: দাম উপযুক্ত কি না | AA18: student দের জন্য ছোট বোতল দাম কম রাখলে ভালো হয়।
A19: 46299.948 | B19: হ্যাঁ, বয়স ১৮ বছর বা বেশি এবং আমি রাজি | C19: ৪৫–৫৪ | D19: নারী | E19: পরিবারের সঙ্গে বাসায় থাকি | F19: Chattogram, Halishahar | G19: Sunsilk hair fall solution | H19: 340 | I19: 460 | J19: ২–৩ বার | K19: চুল রুক্ষ বা শুষ্ক লাগা, স্বাভাবিকের চেয়ে বেশি চুল পড়ছে বলে মনে হওয়া | L19: বয়সের কারণে হয়তো। আর এখানে পানি মাঝেমধ্যে নোনা লাগে। | M19: ওয়াসা বা পৌরসভার সরবরাহ করা পানি | N19: না | O19: প্রযোজ্য নয়—পানি বদলায়নি | P19: কল বা পাত্রে সাদা জমাট দাগ, ব্যবহৃত পানি নোনতা বলে আগে থেকেই মনে হয়েছে | Q19: তেল বা ঘরোয়া যত্ন ব্যবহার করেছি | R19: 4 | S19: 4 | T19: সম্ভবত কিনে দেখতাম | U19: 400 | V19: সম্ভবত কিনে দেখতাম | W19: 340 ml বোতল, ঢাকনায় hardness strip-সহ — 360 টাকা | X19: QR code-এ আঞ্চলিক পানির তথ্য | Y19: দুটির মধ্যে বিশেষ পছন্দ নেই | Z19: ফর্মুলাটি বাস্তবে কাজ করবে কি না | AA19: আমার মেয়ে ফর্মটা পাঠিয়েছে। ধারণা ভালো, কিন্তু QR code আমি নিজে চালাতে পারবো কিনা জানি না, বাংলায় নির্দেশনা থাকলে ভালো।
A20: 46299.996 | B20: হ্যাঁ, বয়স ১৮ বছর বা বেশি এবং আমি রাজি | C20: ১৮–২৪ | D20: পুরুষ | E20: শিক্ষার্থী হিসেবে হোস্টেল বা মেসে থাকি | F20: Gazipur, Boardbazar | G20: head & shoulders anti hairfall | H20: 180 | I20: 340 | J20: ৪–৫ বার | K20: চুল ধোয়ার পরও জমাট বা অবশিষ্ট কিছু থাকার অনুভূতি, স্বাভাবিকের চেয়ে বেশি চুল পড়ছে বলে মনে হওয়া | L20: জানি না, হয়তো হলের খাবার | M20: গভীর নলকূপ | N20: হ্যাঁ | O20: আগের চেয়ে সমস্যা বেশি মনে হয়েছে | P20: কল বা পাত্রে সাদা জমাট দাগ | Q20: শ্যাম্পুর ব্র্যান্ড বা ভ্যারিয়েন্ট বদলেছি | R20: 4 | S20: 3 | T20: সম্ভবত কিনে দেখতাম | U20: 300 | V20: সম্ভবত কিনে দেখতাম | W20: 180 ml বোতল — 180 টাকা | X20: চুলে পানির খনিজ জমা পরিষ্কার করার উদ্দেশ্যে তৈরি ফর্মুলা | Y20: A: সাধারণ ঢাকনা, test strip নেই — 330 টাকা | Z20: ফর্মুলাটি বাস্তবে কাজ করবে কি না
A21: 46300.385 | B21: হ্যাঁ, বয়স ১৮ বছর বা বেশি এবং আমি রাজি | C21: ২৫–৩৪ | D21: নারী | E21: একা বা নিজের সংসার নিয়ে আলাদা বাসায় থাকি | F21: Dhaka, Khilgaon | G21: Pantene total damage care | H21: 340 | I21: 540 | J21: ২–৩ বার | K21: চুল রুক্ষ বা শুষ্ক লাগা, চুল ভেঙে যাওয়া | M21: ওয়াসা বা পৌরসভার সরবরাহ করা পানি | N21: হ্যাঁ | O21: আগের চেয়ে সমস্যা কম মনে হয়েছে | P21: খেয়াল করিনি বা জানি না | Q21: শ্যাম্পুর ব্র্যান্ড বা ভ্যারিয়েন্ট বদলেছি | R21: 4 | S21: 5 | T21: সম্ভবত কিনে দেখতাম | U21: 400 | V21: সম্ভবত কিনে দেখতাম | W21: 340 ml বোতল, ঢাকনায় hardness strip-সহ — 360 টাকা | X21: ঢাকনায় hardness test strip | Y21: B: ঢাকনায় hardness test strip আছে — 360 টাকা | Z21: Strip-এর ফল কতটা নির্ভরযোগ্য | AA21: strip এর রং দেখে কী বুঝবো সেটা ঢাকনার ভিতরেই ছোট চার্টে দিয়ে দিলে ভালো হয়।
A22: 46300.473 | B22: হ্যাঁ, বয়স ১৮ বছর বা বেশি এবং আমি রাজি | C22: ১৮–২৪ | D22: পুরুষ | E22: পরিবারের সঙ্গে বাসায় থাকি | F22: Satkhira, Shyamnagar | G22: সানসিল্ক কালোটা | H22: 6 | I22: 5 | J22: ১ বার | K22: চুল রুক্ষ বা শুষ্ক লাগা, শ্যাম্পুতে কম ফেনা হওয়া, চুল ভেঙে যাওয়া | L22: আমাদের এলাকার পানি লবণ, পুকুরের পানিতে গোসল করি। চুল শক্ত হয়ে যায়। | M22: পুকুর বা নদী | N22: না | O22: প্রযোজ্য নয়—পানি বদলায়নি | P22: ব্যবহৃত পানি নোনতা বলে আগে থেকেই মনে হয়েছে | Q22: তেল বা ঘরোয়া যত্ন ব্যবহার করেছি | R22: 4 | S22: 4 | T22: সম্ভবত কিনে দেখতাম | U22: 150 | V22: সম্ভবত কিনতাম না | W22: 6 ml স্যাশে — 3 টাকা | X22: কম টাকা খরচ করে স্যাশে দিয়ে চেষ্টা করার সুযোগ | Y22: কোনোটিই কিনতাম না | Z22: দাম উপযুক্ত কি না | AA22: আমাদের গ্রামে বোতল কেউ কেনে না, সবাই মিনিপ্যাক কেনে। লবণ পানির জন্য আলাদা কিছু হলে খুব ভালো হতো।
A23: 46300.486 | B23: হ্যাঁ, বয়স ১৮ বছর বা বেশি এবং আমি রাজি | C23: ১৮–২৪ | D23: নারী | E23: শিক্ষার্থী হিসেবে হোস্টেল বা মেসে থাকি | F23: Dhaka, Azimpur | G23: dove | J23: ২–৩ বার | K23: চুলে জট পড়া, স্বাভাবিকের চেয়ে বেশি চুল পড়ছে বলে মনে হওয়া | L23: ঘুম কম, টেনশন | M23: ওয়াসা বা পৌরসভার সরবরাহ করা পানি | N23: মনে নেই বা নিশ্চিত নই | O23: বুঝতে পারিনি | P23: বালতি, বেসিন বা বাথরুমে হলুদ/কমলা/বাদামি দাগ | Q23: তেল বা ঘরোয়া যত্ন ব্যবহার করেছি, মেথি বাটা লাগিয়েছি | R23: 5 | S23: 4 | T23: সম্ভবত কিনে দেখতাম | U23: 350 | V23: সম্ভবত কিনে দেখতাম | W23: 6 ml স্যাশে — 3 টাকা | X23: চুলে পানির খনিজ জমা পরিষ্কার করার উদ্দেশ্যে তৈরি ফর্মুলা | Y23: B: ঢাকনায় hardness test strip আছে — 360 টাকা | Z23: আমার চুল বা মাথার ত্বকের সঙ্গে মানাবে কি না
A24: 46300.511 | B24: হ্যাঁ, বয়স ১৮ বছর বা বেশি এবং আমি রাজি | C24: ২৫–৩৪ | D24: পুরুষ | E24: কোম্পানির দেওয়া ডরমিটরিতে থাকি | F24: Chattogram, Bayezid | G24: Clear | H24: 330 | I24: 500 | J24: ৬ বার বা বেশি | K24: চুল ধোয়ার পরও জমাট বা অবশিষ্ট কিছু থাকার অনুভূতি, খুশকি বা মাথার ত্বকে চুলকানি, মাথার ত্বক তৈলাক্ত হয়ে যায় | L24: অফিস থেকে ফিরে প্রতিদিন গোসল করি, চুল চটচটে লাগে। কারণ জানি না। | M24: জানি না | N24: না | O24: প্রযোজ্য নয়—পানি বদলায়নি | P24: কল বা পাত্রে সাদা জমাট দাগ | Q24: শ্যাম্পুর ব্র্যান্ড বা ভ্যারিয়েন্ট বদলেছি | R24: 2 | S24: 3 | T24: সম্ভবত কিনতাম না | U24: 250 | V24: সম্ভবত কিনতাম না | W24: কোনোটিই কিনতাম না | X24: কোনোটিই বিশেষ মূল্যবান মনে হচ্ছে না | Y24: দুটির মধ্যে বিশেষ পছন্দ নেই | Z24: বর্তমান শ্যাম্পু বদলানোর যথেষ্ট কারণ আছে কি না | AA24: শ্যাম্পু তো শ্যাম্পুই, strip দিয়ে কী হবে বুঝলাম না। marketing মনে হচ্ছে।
A25: 46300.929 | B25: হ্যাঁ, বয়স ১৮ বছর বা বেশি এবং আমি রাজি | C25: ১৮–২৪ | D25: নারী | E25: শিক্ষার্থী হিসেবে হোস্টেল বা মেসে থাকি | F25: Rajshahi, Kazla | G25: Sunsilk black shine | H25: 340 | I25: 440 | J25: ২–৩ বার | K25: চুল রুক্ষ বা শুষ্ক লাগা, চুলে জট পড়া, চুল ধোয়ার পরও জমাট বা অবশিষ্ট কিছু থাকার অনুভূতি | L25: রাজশাহীর পানি ভারী, বাসার চেয়ে এখানে চুল অনেক খারাপ হয়ে গেছে | M25: গভীর নলকূপ | N25: হ্যাঁ | O25: আগের চেয়ে সমস্যা বেশি মনে হয়েছে | P25: বালতি, বেসিন বা বাথরুমে হলুদ/কমলা/বাদামি দাগ, কল বা পাত্রে সাদা জমাট দাগ | Q25: শ্যাম্পুর ব্র্যান্ড বা ভ্যারিয়েন্ট বদলেছি, তেল বা ঘরোয়া যত্ন ব্যবহার করেছি, ফিল্টার করা বা কিনে আনা পানি ব্যবহার করেছি | R25: 5 | S25: 5 | T25: অবশ্যই কিনে দেখতাম | U25: 450 | V25: অবশ্যই কিনে দেখতাম | W25: 340 ml বোতল, ঢাকনায় hardness strip-সহ — 360 টাকা | X25: চুলে পানির খনিজ জমা পরিষ্কার করার উদ্দেশ্যে তৈরি ফর্মুলা | Y25: B: ঢাকনায় hardness test strip আছে — 360 টাকা | Z25: বিশেষ কোনো সংশয় নেই | AA25: রাজশাহীতে খুব দরকার এরকম কিছু। কবে বাজারে আসবে? হলের সবাইকে বলবো।
A26: 46300.979 | B26: হ্যাঁ, বয়স ১৮ বছর বা বেশি এবং আমি রাজি | C26: ১৮–২৪ | D26: বলতে চাই না | E26: শিক্ষার্থী হিসেবে হোস্টেল বা মেসে থাকি | F26: Sylhet, Tilagor | G26: H&S | H26: 180 | I26: 340 | J26: ৪–৫ বার | K26: খুশকি বা মাথার ত্বকে চুলকানি | L26: জানি না | M26: মেসের ট্যাংকির পানি, কোথা থেকে আসে জানি না | N26: না | O26: প্রযোজ্য নয়—পানি বদলায়নি | P26: খেয়াল করিনি বা জানি না | Q26: শ্যাম্পুর ব্র্যান্ড বা ভ্যারিয়েন্ট বদলেছি | R26: 4 | S26: 4 | T26: সম্ভবত কিনে দেখতাম | U26: 300 | V26: সম্ভবত কিনে দেখতাম | W26: 180 ml বোতল — 180 টাকা | X26: ঢাকনায় hardness test strip | Y26: A: সাধারণ ঢাকনা, test strip নেই — 330 টাকা | Z26: দাম উপযুক্ত কি না
A27: 46301.018 | B27: হ্যাঁ, বয়স ১৮ বছর বা বেশি এবং আমি রাজি | C27: ৩৫–৪৪ | D27: নারী | E27: পরিবারের সঙ্গে বাসায় থাকি | F27: বরিশাল সদর | G27: Sunsilk | H27: 340 | I27: 450 | J27: ২–৩ বার | K27: চুল রুক্ষ বা শুষ্ক লাগা, চুলে জট পড়া, স্বাভাবিকের চেয়ে বেশি চুল পড়ছে বলে মনে হওয়া | L27: মনে হয় পানি আর শ্যাম্পুর মান দুটোই | M27: ওয়াসা বা পৌরসভার সরবরাহ করা পানি | N27: না | O27: প্রযোজ্য নয়—পানি বদলায়নি | P27: বালতি, বেসিন বা বাথরুমে হলুদ/কমলা/বাদামি দাগ, ব্যবহৃত পানি নোনতা বলে আগে থেকেই মনে হয়েছে | Q27: শ্যাম্পুর ব্র্যান্ড বা ভ্যারিয়েন্ট বদলেছি, তেল বা ঘরোয়া যত্ন ব্যবহার করেছি | R27: 4 | S27: 4 | T27: সম্ভবত কিনে দেখতাম | U27: 350 | V27: সম্ভবত কিনে দেখতাম | W27: 180 ml বোতল — 180 টাকা | X27: দেশি কোম্পানির পণ্য হওয়া | Y27: দুটির মধ্যে বিশেষ পছন্দ নেই | Z27: বাচ্চাদের জন্য নিরাপদ কিনা | AA27: বাচ্চাদের জন্যও ব্যবহার করা যাবে কিনা জানাবেন।
A28: 46301.034 | B28: হ্যাঁ, বয়স ১৮ বছর বা বেশি এবং আমি রাজি | C28: ১৮–২৪ | D28: পুরুষ | E28: পরিবারের সঙ্গে বাসায় থাকি | F28: Dinajpur sadar | G28: Garnier Fructis | H28: 175 | I28: 330 | J28: ২–৩ বার | K28: চুলে জট পড়া, স্বাভাবিকের চেয়ে বেশি চুল পড়ছে বলে মনে হওয়া | M28: অগভীর নলকূপ | N28: না | O28: তেমন পার্থক্য হয়নি | P28: বালতি, বেসিন বা বাথরুমে হলুদ/কমলা/বাদামি দাগ | Q28: কোনো ব্যবস্থা নিইনি | R28: 3 | S28: 4 | T28: এখনো সিদ্ধান্ত নিতে পারছি না | U28: 250 | V28: সম্ভবত কিনতাম না | W28: 6 ml স্যাশে — 3 টাকা | X28: কম টাকা খরচ করে স্যাশে দিয়ে চেষ্টা করার সুযোগ | Y28: A: সাধারণ ঢাকনা, test strip নেই — 330 টাকা | Z28: ফর্মুলাটি বাস্তবে কাজ করবে কি না
A29: 46301.414 | B29: হ্যাঁ, বয়স ১৮ বছর বা বেশি এবং আমি রাজি | C29: ১৮–২৪ | D29: নারী | E29: শিক্ষার্থী হিসেবে হোস্টেল বা মেসে থাকি | F29: ঢাকা, পলাশী | G29: Mamaearth onion shampoo | H29: 250 | I29: 450 | J29: ২–৩ বার | K29: চুল রুক্ষ বা শুষ্ক লাগা, চুল ভেঙে যাওয়া, স্বাভাবিকের চেয়ে বেশি চুল পড়ছে বলে মনে হওয়া | L29: হলে আসার পর থেকে চুল পড়া শুরু, সবাই বলে পানির কারণে। তবে খাওয়াদাওয়াও ঠিক নাই। | M29: ওয়াসা বা পৌরসভার সরবরাহ করা পানি | N29: হ্যাঁ | O29: আগের চেয়ে সমস্যা বেশি মনে হয়েছে | P29: বালতি, বেসিন বা বাথরুমে হলুদ/কমলা/বাদামি দাগ | Q29: শ্যাম্পুর ব্র্যান্ড বা ভ্যারিয়েন্ট বদলেছি, তেল বা ঘরোয়া যত্ন ব্যবহার করেছি, ফিল্টার করা বা কিনে আনা পানি ব্যবহার করেছি | R29: 5 | S29: 4 | T29: অবশ্যই কিনে দেখতাম | U29: 400 | V29: সম্ভবত কিনে দেখতাম | W29: 340 ml বোতল, ঢাকনায় hardness strip-সহ — 360 টাকা | X29: চুলে পানির খনিজ জমা পরিষ্কার করার উদ্দেশ্যে তৈরি ফর্মুলা | Y29: B: ঢাকনায় hardness test strip আছে — 360 টাকা | Z29: ফর্মুলাটি বাস্তবে কাজ করবে কি না | AA29: online এ (দারাজ/নিজস্ব পেজ) পাওয়া গেলে ভালো। সালফেট ফ্রি কিনা জানাবেন।
A30: 46301.461 | B30: হ্যাঁ, বয়স ১৮ বছর বা বেশি এবং আমি রাজি | C30: ৩৫–৪৪ | D30: পুরুষ | E30: একা বা নিজের সংসার নিয়ে আলাদা বাসায় থাকি | F30: কুমিল্লা, লাকসাম | G30: clear men | H30: 330 | I30: 520 | J30: ৪–৫ বার | K30: চুল ধোয়ার পরও জমাট বা অবশিষ্ট কিছু থাকার অনুভূতি, খুশকি বা মাথার ত্বকে চুলকানি | L30: পানিতে আয়রন। | M30: অগভীর নলকূপ | N30: না | O30: প্রযোজ্য নয়—পানি বদলায়নি | P30: বালতি, বেসিন বা বাথরুমে হলুদ/কমলা/বাদামি দাগ | Q30: শ্যাম্পুর ব্র্যান্ড বা ভ্যারিয়েন্ট বদলেছি, ফিল্টার করা বা কিনে আনা পানি ব্যবহার করেছি | R30: 4 | S30: 5 | T30: সম্ভবত কিনে দেখতাম | U30: 380 | V30: সম্ভবত কিনে দেখতাম | W30: 340 ml বোতল, ঢাকনায় hardness strip-সহ — 360 টাকা | X30: ঢাকনায় hardness test strip | Y30: B: ঢাকনায় hardness test strip আছে — 360 টাকা | Z30: Strip-এর ফল কতটা নির্ভরযোগ্য | AA30: strip দিয়ে আয়রনও মাপা গেলে ১০০% কিনতাম।
A31: 46301.518 | B31: হ্যাঁ, বয়স ১৮ বছর বা বেশি এবং আমি রাজি | C31: ১৮–২৪ | D31: নারী | E31: শিক্ষার্থী হিসেবে হোস্টেল বা মেসে থাকি | F31: খুলনা, সোনাডাঙ্গা | G31: সানসিল্ক হেয়ার ফল | H31: 180 | I31: 250 | J31: ২–৩ বার | K31: চুল রুক্ষ বা শুষ্ক লাগা, শ্যাম্পুতে কম ফেনা হওয়া, স্বাভাবিকের চেয়ে বেশি চুল পড়ছে বলে মনে হওয়া | L31: খুলনার পানি নোনা, ফেনা কম হয়। | M31: ওয়াসা বা পৌরসভার সরবরাহ করা পানি | N31: হ্যাঁ | O31: আগের চেয়ে সমস্যা বেশি মনে হয়েছে | P31: বালতি, বেসিন বা বাথরুমে হলুদ/কমলা/বাদামি দাগ, ব্যবহৃত পানি নোনতা বলে আগে থেকেই মনে হয়েছে | Q31: শ্যাম্পুর ব্র্যান্ড বা ভ্যারিয়েন্ট বদলেছি, তেল বা ঘরোয়া যত্ন ব্যবহার করেছি | R31: 4 | S31: 4 | T31: সম্ভবত কিনে দেখতাম | U31: 320 | V31: সম্ভবত কিনে দেখতাম | W31: 180 ml বোতল — 180 টাকা | X31: চুলে পানির খনিজ জমা পরিষ্কার করার উদ্দেশ্যে তৈরি ফর্মুলা | Y31: দুটির মধ্যে বিশেষ পছন্দ নেই | Z31: ফর্মুলাটি বাস্তবে কাজ করবে কি না
A32: 46301.529 | B32: হ্যাঁ, বয়স ১৮ বছর বা বেশি এবং আমি রাজি | C32: ১৮–২৪ | D32: পুরুষ | E32: শিক্ষার্থী হিসেবে হোস্টেল বা মেসে থাকি | F32: Chattogram, Hathazari | G32: head and shoulders cool menthol | H32: 180 | I32: 350 | J32: ৬ বার বা বেশি | K32: চুল ধোয়ার পরও জমাট বা অবশিষ্ট কিছু থাকার অনুভূতি, খুশকি বা মাথার ত্বকে চুলকানি | M32: গভীর নলকূপ | N32: হ্যাঁ | O32: বুঝতে পারিনি | P32: কল বা পাত্রে সাদা জমাট দাগ | Q32: শ্যাম্পুর ব্র্যান্ড বা ভ্যারিয়েন্ট বদলেছি | R32: 4 | S32: 5 | T32: সম্ভবত কিনে দেখতাম | U32: 300 | V32: সম্ভবত কিনে দেখতাম | W32: 6 ml স্যাশে — 3 টাকা | X32: ঢাকনায় hardness test strip | Y32: B: ঢাকনায় hardness test strip আছে — 360 টাকা | Z32: Strip ব্যবহার করা সহজ হবে কি না | AA32: ছেলেদের জন্য menthol ভার্সন থাকলে ভালো হয়।
A33: 46301.574 | B33: হ্যাঁ, বয়স ১৮ বছর বা বেশি এবং আমি রাজি | C33: ২৫–৩৪ | D33: নারী | E33: পরিবারের সঙ্গে বাসায় থাকি | F33: Dhaka, Rampura | G33: Dove daily shine | H33: 340 | I33: 540 | J33: ২–৩ বার | K33: চুল রুক্ষ বা শুষ্ক লাগা | L33: জানি না | M33: ওয়াসা বা পৌরসভার সরবরাহ করা পানি | N33: না | O33: প্রযোজ্য নয়—পানি বদলায়নি | P33: বালতি, বেসিন বা বাথরুমে হলুদ/কমলা/বাদামি দাগ | Q33: শ্যাম্পুর ব্র্যান্ড বা ভ্যারিয়েন্ট বদলেছি | R33: 4 | S33: 3 | T33: সম্ভবত কিনে দেখতাম | U33: 400 | V33: সম্ভবত কিনে দেখতাম | W33: 6 ml স্যাশে — 3 টাকা | X33: চুলে পানির খনিজ জমা পরিষ্কার করার উদ্দেশ্যে তৈরি ফর্মুলা | Y33: B: ঢাকনায় hardness test strip আছে — 360 টাকা | Z33: আমার চুল বা মাথার ত্বকের সঙ্গে মানাবে কি না
A34: 46301.853 | B34: হ্যাঁ, বয়স ১৮ বছর বা বেশি এবং আমি রাজি | C34: ৫৫ বা বেশি | D34: পুরুষ | E34: পরিবারের সঙ্গে বাসায় থাকি | F34: Rajshahi, Boalia | G34: ব্যবহার করি না | J34: শ্যাম্পু ব্যবহার করি না | K34: চুল রুক্ষ বা শুষ্ক লাগা | M34: ওয়াসা বা পৌরসভার সরবরাহ করা পানি | N34: না | O34: প্রযোজ্য নয়—পানি বদলায়নি | P34: কল বা পাত্রে সাদা জমাট দাগ | Q34: কোনো ব্যবস্থা নিইনি | R34: 2 | S34: 1 | T34: একেবারেই কিনতাম না | U34: 0 | V34: একেবারেই কিনতাম না | W34: কোনোটিই কিনতাম না | X34: কোনোটিই বিশেষ মূল্যবান মনে হচ্ছে না | Y34: কোনোটিই কিনতাম না | Z34: বর্তমান শ্যাম্পু বদলানোর যথেষ্ট কারণ আছে কি না | AA34: আমার শ্যাম্পু লাগে না, সাবানেই চলে।
A35: 46301.925 | B35: হ্যাঁ, বয়স ১৮ বছর বা বেশি এবং আমি রাজি | C35: ১৮–২৪ | D35: নারী | E35: পরিবারের সঙ্গে বাসায় থাকি | F35: Narayanganj, Fatullah | G35: Sunsilk lusciously thick & long | H35: 180 | I35: 240 | J35: ৪–৫ বার | K35: চুলে জট পড়া, স্বাভাবিকের চেয়ে বেশি চুল পড়ছে বলে মনে হওয়া, খুশকি বা মাথার ত্বকে চুলকানি | L35: ধুলাবালি আর ফ্যাক্টরির ধোঁয়া | M35: ওয়াসা বা পৌরসভার সরবরাহ করা পানি | N35: না | O35: প্রযোজ্য নয়—পানি বদলায়নি | P35: বালতি, বেসিন বা বাথরুমে হলুদ/কমলা/বাদামি দাগ | Q35: শ্যাম্পুর ব্র্যান্ড বা ভ্যারিয়েন্ট বদলেছি, তেল বা ঘরোয়া যত্ন ব্যবহার করেছি | R35: 4 | S35: 4 | T35: সম্ভবত কিনে দেখতাম | U35: 300 | V35: সম্ভবত কিনে দেখতাম | W35: 6 ml স্যাশে — 3 টাকা | X35: কম টাকা খরচ করে স্যাশে দিয়ে চেষ্টা করার সুযোগ | Y35: A: সাধারণ ঢাকনা, test strip নেই — 330 টাকা | Z35: দাম উপযুক্ত কি না
A36: 46302.423 | B36: হ্যাঁ, বয়স ১৮ বছর বা বেশি এবং আমি রাজি | C36: ২৫–৩৪ | D36: পুরুষ | E36: শিক্ষার্থী নই; মেস বা ভাগাভাগি বাসায় থাকি | F36: Dhaka, Mirpur 1 | G36: Clear | H36: 180 | I36: 320 | J36: ৬ বার বা বেশি | K36: স্বাভাবিকের চেয়ে বেশি চুল পড়ছে বলে মনে হওয়া, খুশকি বা মাথার ত্বকে চুলকানি | L36: রোদে কাজ করি, ঘাম আর ধুলা | M36: ওয়াসা বা পৌরসভার সরবরাহ করা পানি | N36: না | O36: প্রযোজ্য নয়—পানি বদলায়নি | P36: খেয়াল করিনি বা জানি না | Q36: শ্যাম্পুর ব্র্যান্ড বা ভ্যারিয়েন্ট বদলেছি | R36: 4 | S36: 3 | T36: সম্ভবত কিনে দেখতাম | U36: 300 | V36: সম্ভবত কিনে দেখতাম | W36: 6 ml স্যাশে — 3 টাকা | X36: কম টাকা খরচ করে স্যাশে দিয়ে চেষ্টা করার সুযোগ | Y36: A: সাধারণ ঢাকনা, test strip নেই — 330 টাকা | Z36: দোকানে পাওয়া যাবে কি না | AA36: এলাকার দোকানে না পাওয়া গেলে কেউ কিনবে না। মুদি দোকানে দিতে হবে।
A37: 46302.601 | B37: হ্যাঁ, বয়স ১৮ বছর বা বেশি এবং আমি রাজি | C37: ১৮–২৪ | D37: নারী | E37: শিক্ষার্থী হিসেবে হোস্টেল বা মেসে থাকি | F37: ময়মনসিংহ সদর | G37: Pantene | H37: 180 | I37: 290 | J37: ২–৩ বার | K37: চুল রুক্ষ বা শুষ্ক লাগা, চুলে জট পড়া, চুল ধোয়ার পরও জমাট বা অবশিষ্ট কিছু থাকার অনুভূতি, স্বাভাবিকের চেয়ে বেশি চুল পড়ছে বলে মনে হওয়া | L37: হলের পানিতে আয়রন, সাদা কাপড়ে দাগ পড়ে | M37: গভীর নলকূপ | N37: হ্যাঁ | O37: আগের চেয়ে সমস্যা বেশি মনে হয়েছে | P37: বালতি, বেসিন বা বাথরুমে হলুদ/কমলা/বাদামি দাগ | Q37: শ্যাম্পুর ব্র্যান্ড বা ভ্যারিয়েন্ট বদলেছি, তেল বা ঘরোয়া যত্ন ব্যবহার করেছি, ফিল্টার করা বা কিনে আনা পানি ব্যবহার করেছি | R37: 5 | S37: 5 | T37: অবশ্যই কিনে দেখতাম | U37: 400 | V37: সম্ভবত কিনে দেখতাম | W37: 340 ml বোতল, ঢাকনায় hardness strip-সহ — 360 টাকা | X37: চুলে পানির খনিজ জমা পরিষ্কার করার উদ্দেশ্যে তৈরি ফর্মুলা | Y37: B: ঢাকনায় hardness test strip আছে — 360 টাকা | Z37: ফর্মুলাটি বাস্তবে কাজ করবে কি না | AA37: এরকম research based পণ্য দেশে বানালে ভালো লাগবে। মেয়েদের হলের জন্য প্রমোশন করলে ভালো সাড়া পাবেন।
A38: 46302.751 | B38: হ্যাঁ, বয়স ১৮ বছর বা বেশি এবং আমি রাজি | C38: ২৫–৩৪ | D38: নারী | E38: শিক্ষার্থী নই; মেস বা ভাগাভাগি বাসায় থাকি | F38: Dhaka, Tejgaon | G38: Sunsilk black shine | H38: 340 | I38: 430 | J38: ২–৩ বার | K38: চুল রুক্ষ বা শুষ্ক লাগা, স্বাভাবিকের চেয়ে বেশি চুল পড়ছে বলে মনে হওয়া | L38: জানি না, তবে মেস বদলানোর পর বেড়েছে | M38: কিনে আনা পানি বা ট্যাংকারের পানি | N38: হ্যাঁ | O38: আগের চেয়ে সমস্যা বেশি মনে হয়েছে | P38: কল বা পাত্রে সাদা জমাট দাগ | Q38: শ্যাম্পুর ব্র্যান্ড বা ভ্যারিয়েন্ট বদলেছি, হেয়ার সিরাম | R38: 4 | S38: 4 | T38: সম্ভবত কিনে দেখতাম | U38: 350 | V38: সম্ভবত কিনে দেখতাম | W38: 180 ml বোতল — 180 টাকা | X38: চুলে পানির খনিজ জমা পরিষ্কার করার উদ্দেশ্যে তৈরি ফর্মুলা | Y38: B: ঢাকনায় hardness test strip আছে — 360 টাকা | Z38: ফর্মুলাটি বাস্তবে কাজ করবে কি না
A39: 46302.858 | B39: হ্যাঁ, বয়স ১৮ বছর বা বেশি এবং আমি রাজি | C39: ৩৫–৪৪ | D39: পুরুষ | E39: একা বা নিজের সংসার নিয়ে আলাদা বাসায় থাকি | F39: সিলেট সদর | G39: Sunsilk (বউ যেটা আনে) | H39: 340 | J39: সপ্তাহে একবারের কম | K39: কোনোটিই নয় | M39: ওয়াসা বা পৌরসভার সরবরাহ করা পানি | N39: না | O39: প্রযোজ্য নয়—পানি বদলায়নি | P39: খেয়াল করিনি বা জানি না | Q39: কোনো ব্যবস্থা নিইনি | R39: 3 | S39: 3 | T39: এখনো সিদ্ধান্ত নিতে পারছি না | V39: এখনো সিদ্ধান্ত নিতে পারছি না | W39: 180 ml বোতল — 180 টাকা | X39: QR code-এ আঞ্চলিক পানির তথ্য | Y39: দুটির মধ্যে বিশেষ পছন্দ নেই | Z39: বর্তমান শ্যাম্পু বদলানোর যথেষ্ট কারণ আছে কি না | AA39: পরিবারের জন্য কিনলে বউ সিদ্ধান্ত নেবে 🙂
A40: 46302.87 | B40: হ্যাঁ, বয়স ১৮ বছর বা বেশি এবং আমি রাজি | C40: ১৮–২৪ | D40: নারী | E40: শিক্ষার্থী হিসেবে হোস্টেল বা মেসে থাকি | F40: কুষ্টিয়া সদর | G40: TRESemme hair fall defence | H40: 180 | I40: 380 | J40: ২–৩ বার | K40: চুল রুক্ষ বা শুষ্ক লাগা, চুলে জট পড়া, চুল ধোয়ার পরও জমাট বা অবশিষ্ট কিছু থাকার অনুভূতি | L40: পানি খুব খর মনে হয়, সাবানে ফেনা হয় না | M40: গভীর নলকূপ | N40: হ্যাঁ | O40: আগের চেয়ে সমস্যা বেশি মনে হয়েছে | P40: কল বা পাত্রে সাদা জমাট দাগ | Q40: শ্যাম্পুর ব্র্যান্ড বা ভ্যারিয়েন্ট বদলেছি, তেল বা ঘরোয়া যত্ন ব্যবহার করেছি | R40: 5 | S40: 5 | T40: অবশ্যই কিনে দেখতাম | U40: 380 | V40: অবশ্যই কিনে দেখতাম | W40: 340 ml বোতল, ঢাকনায় hardness strip-সহ — 360 টাকা | X40: ঢাকনায় hardness test strip | Y40: B: ঢাকনায় hardness test strip আছে — 360 টাকা | Z40: Strip-এর ফল কতটা নির্ভরযোগ্য | AA40: strip কতদিন ভালো থাকবে (expiry) সেটা জানাবেন। আর ঘ্রাণ যেন হালকা হয়।
...

Sheet Q11 কোডিং
A1: Response row | B1: Q11 উত্তর (হুবহু) | C1: নিজে থেকে পানি উল্লেখ?
A2: 2 | B2: হলের পানিতে মনে হয় সমস্যা আছে, বাসায় থাকতে এত চুল পড়ত না। | C2: হ্যাঁ
A3: 3 | B3: রাজশাহীর পানি খর, বালতিতে সাদা দাগ পড়ে যায়। চুলেও মনে হয় ওইটাই জমে। | C3: হ্যাঁ
A4: 4 | B4: ডেলিভারির পর থেকে চুল পড়া বেড়েছে, হরমোনের কারণে হতে পারে। | C4: না
A5: 5 | B5: পানি লবণাক্ত, ফেনা হয়না ঠিকমতো | C5: হ্যাঁ
A6: 6 | B6: জানি না। হয়তো ধুলাবালি। | C6: না
A7: 7 | B7: এখানকার পানিতে আয়রন বেশি, সাদা গেঞ্জি হলুদ হয়ে যায়। | C7: হ্যাঁ
A8: 8 | B8: বৃষ্টির সময় চুল বেশি জট পাকে, আর হোস্টেলের পানিও ঠিক না | C8: হ্যাঁ
A9: 9 | B9: খুশকি পুরান সমস্যা। | C9: না
A10: 11 | B10: মেসের পানিতে কেমন যেন গন্ধ, চুল ধোয়ার পর চটচটে লাগে। | C10: হ্যাঁ
A11: 13 | B11: বাড্ডায় আসার পর থেকে চুল ঝরছে বেশি, পানির কারণে কিনা বুঝি না, আবার কাজের চাপও আছে। | C11: হ্যাঁ
A12: 14 | B12: শীত আসলে খুশকি বাড়ে | C12: না
A13: 15 | B13: নোয়াখালীর পানিতে প্রচুর আয়রন, বালতি লাল হয়ে যায়। চুল খড়ের মত লাগে। | C13: হ্যাঁ
... A42: 51 | B42: শ্যাম্পু সুট করে না মনে হয় | C42: না

Sheet Simulation key
A1: Response row | B1: Timestamp | C1: Q2 (ফর্মে যা আছে) | D1: ধরে নেওয়া আসল বয়স
A2: 2 | B2: 46298.818 | C2: ১৮–২৪ | D2: 21
A3: 3 | B3: 46298.835 | C3: ১৮–২৪ | D3: 20
A4: 4 | B4: 46298.838 | C4: ২৫–৩৪ | D4: 31
A5: 5 | B5: 46298.858 | C5: ১৮–২৪ | D5: 22
A6: 6 | B6: 46298.86 | C6: ১৮–২৪ | D6: 24
A7: 7 | B7: 46298.883 | C7: ২৫–৩৪ | D7: 27
A8: 8 | B8: 46298.901 | C8: ১৮–২৪ | D8: 18
A9: 9 | B9: 46298.937 | C9: ৩৫–৪৪ | D9: 41
A10: 11 | B10: 46299.628 | C10: ১৮–২৪ | D10: 19
A11: 12 | B11: 46299.65 | C11: ১৮–২৪ | D11: 23
A12: 13 | B12: 46299.677 | C12: ২৫–৩৪ | D12: 30
A13: 14 | B13: 46299.896 | C13: ১৮–২৪ | D13: 19
... A50: 51 | B50: 46304.967 | C50: ১৮–২৪ | D50: 18
